Workbook

Sheet Cash ABC+ACZ
A2: =CR2&" ("&CI2&")" -> RCASH ÜÇÜN KƏSİM QAYDALARI (ABC + ACZ) | CI2: ABC + ACZ | CR2: RCASH ÜÇÜN KƏSİM QAYDALARI
A3: Qayda № | G3: Qərar | K3: Qaydanın Təsviri | Z3: Limitlər | AO3: Parametrlər | BD3: İmtina Səbəbi (ID və Mətn) | BU3: X gündən sonra kredit üçün müraciət edə bilər | BZ3: Prioritet
A4: Prioritet 1. Loan Workbench (LW) - Müştərinin Daxili LV sistemində yoxlanması | AO4: Qerar Sutunu | AP4: Kesim Noqtesi | AQ4: Ekspert Penceresi
A5: R_1010 | G5: QƏBUL | K5: Müştəri qara siyahıdadır | AO5: REJECT | AP5: Var | AQ5: Bu halda Skoring Sistemi Musteriye Imtina Verib. Istinsna Hallari Nezere alinaraq ekspertin qarsisina cixarilir. | AU5: Qara siyahi | BD5: 010 | BG5: =IFERROR(VLOOKUP('Cash ABC+ACZ'!BD5,Lookups111!A$4:B$38,2,FALSE()),"") -> Qara siyahı | BZ5: 1
A6: R_1020 | G6: QƏBUL | K6: Gəlir kifayət etmir | AO6: REJECT | AP6: Var | AQ6: Bu halda Skoring Sistemi Musteriye Imtina Verib. Istinsna Hallari Nezere alinaraq ekspertin qarsisina cixarilir. | AU6: Gelir kifayet etmir | BD6: 005 | BG6: =IFERROR(VLOOKUP('Cash ABC+ACZ'!BD6,Lookups111!A$4:B$38,2,FALSE()),"") -> Gəliri kifayət etmir | BU6: 15 | BZ6: 2
A7: R_1030 | G7: QƏBUL | K7: Mənfi kredit tarixçəsi | AO7: REJECT | AP7: Var | AQ7: Bu halda Skoring Sistemi Musteriye Imtina Verib. Istinsna Hallari Nezere alinaraq ekspertin qarsisina cixarilir. | AU7: Menfi kredit tarixcesi | BD7: 020 | BG7: =IFERROR(VLOOKUP('Cash ABC+ACZ'!BD7,Lookups111!A$4:B$38,2,FALSE()),"") -> Mənfi kredit tarixçəsi | BU7: 90 | BZ7: 3
A8: R_1040 | G8: QƏBUL | K8: Ailə üzvlərində mənfi tarixçə | AO8: REJECT | AP8: Var | AQ8: Bu halda Skoring Sistemi Musteriye Imtina Verib. Istinsna Hallari Nezere alinaraq ekspertin qarsisina cixarilir. | AU8: Aile uzvlerinin menfi tarixcesi | BD8: 030 | BG8: =IFERROR(VLOOKUP('Cash ABC+ACZ'!BD8,Lookups111!A$4:B$38,2,FALSE()),"") -> Ailə üzvlərinin mənfi tarixçəsi | BU8: 15 | BZ8: 4
A9: R_1050 | G9: QƏBUL | K9: Yanlış məlumat | AO9: REJECT | AP9: Var | AQ9: Bu halda Skoring Sistemi Musteriye Imtina Verib. Istinsna Hallari Nezere alinaraq ekspertin qarsisina cixarilir. | AU9: Yalan melumat | BD9: 070 | BG9: =IFERROR(VLOOKUP('Cash ABC+ACZ'!BD9,Lookups111!A$4:B$38,2,FALSE()),"") -> Yalan məlumat | BU9: 15 | BZ9: 5
A10: R_1060 | G10: QƏBUL | K10: Borc yükü yüksəkdir | AO10: REJECT | AP10: Var | AQ10: Bu halda Skoring Sistemi Musteriye Imtina Verib. Istinsna Hallari Nezere alinaraq ekspertin qarsisina cixarilir. | AU10: Borc yukluliyu coxdur | BD10: 080 | BG10: =IFERROR(VLOOKUP('Cash ABC+ACZ'!BD10,Lookups111!A$4:B$38,2,FALSE()),"") -> Borc yüklülüyü çoxdur | BU10: 3 | BZ10: 6
A11: R_1070 | G11: QƏBUL | K11: İş stajı azdır | AO11: REJECT | AP11: Var | AQ11: Bu halda Skoring Sistemi Musteriye Imtina Verib. Istinsna Hallari Nezere alinaraq ekspertin qarsisina cixarilir. | AU11: Emek staji azdir | BD11: 110 | BG11: =IFERROR(VLOOKUP('Cash ABC+ACZ'!BD11,Lookups111!A$4:B$38,2,FALSE()),"") -> Əmək stajı azdır | BU11: 3 | BZ11: 7
A12: R_1080 | G12: QƏBUL | K12: Kobud rəftar | AO12: REJECT | AP12: Var | AQ12: Bu halda Skoring Sistemi Musteriye Imtina Verib. Istinsna Hallari Nezere alinaraq ekspertin qarsisina cixarilir. | AU12: Kobud reftar | BD12: 120 | BG12: =IFERROR(VLOOKUP('Cash ABC+ACZ'!BD12,Lookups111!A$4:B$38,2,FALSE()),"") -> Kobud rəftar | BU12: 3 | BZ12: 8
A13: R_1090 | G13: QƏBUL | K13: Embafinansda aktiv nağd kreditinin ən azı yarı müddəti keçməmişdir | AO13: REJECT | AP13: Var | AQ13: Bu halda Skoring Sistemi Musteriye Imtina Verib. Istinsna Hallari Nezere alinaraq ekspertin qarsisina cixarilir. | AU13: Aktiv nagd kredit<50% | BD13: 300 | BG13: =IFERROR(VLOOKUP('Cash ABC+ACZ'!BD13,Lookups111!A$4:B$38,2,FALSE()),"") -> Aktiv nağd kredit < 50% | BZ13: 9
A14: R_1100 | G14: QƏBUL | K14: OnePoint platformasında aktiv kreditləri mövcuddur | AO14: REJECT | AP14: Var | AQ14: Bu halda Skoring Sistemi Musteriye Imtina Verib. Istinsna Hallari Nezere alinaraq ekspertin qarsisina cixarilir. | AU14: Aktiv one point kredit | BD14: 310 | BG14: =IFERROR(VLOOKUP('Cash ABC+ACZ'!BD14,Lookups111!A$4:B$38,2,FALSE()),"") -> Aktiv OnePoint krediti | BZ14: 10
A15: R_1110 | G15: QƏBUL | K15: Embafinansda cari gecikməsi mövcuddur | AO15: REJECT | AP15: Var | AQ15: Bu halda Skoring Sistemi Musteriye Imtina Verib. Istinsna Hallari Nezere alinaraq ekspertin qarsisina cixarilir. | AU15: Cari gecikme | BD15: 320 | BG15: =IFERROR(VLOOKUP('Cash ABC+ACZ'!BD15,Lookups111!A$4:B$38,2,FALSE()),"") -> Cari gecikma | BZ15: 11
A16: Prioritet 2: Asanfinans Şəxsi Məlumatlar
A17: R_2010 | G17: QƏBUL | K17: Yaş həddi | Z17: Min. | AI17: 20 | AO17: Yoxdur | AP17: Var | AQ17: Bu halda Skoring Sistemi Musteriye Imtina Verib. Istinsna Hallari Nezere alinaraq ekspertin qarsisina cixarilir. | AU17: Yaş həddi | BD17: 050 | BG17: =IFERROR(VLOOKUP(BD17,Lookups111!A$4:B$38,2,FALSE()),"") -> Yaş həddi | BZ17: 1
Z18: Maks. | AI18: 65
A19: Prioritet 3: AKB Skor Servisi | AO19: Qerar Sutunu | AP19: Kesim Noqtesi | AQ19: Ekspert Penceresi
A20: AB: Şəxsin cari dövr üzrə aktiv öhdəliyində yüksək gecikmə günləri mövcuddur | AO20: REJECT | AP20: Var | AQ20: Bu halda Skoring Sistemi Musteriye Imtina Verib. Istinsna Hallari Nezere alinaraq ekspertin qarsisina cixarilir. | AU20: AB: Şəxsin cari dövr üzrə aktiv öhdəliyində yüksək gecikmə günləri mövcuddur
A21: TY – Şəxsin yaşı 16-dan kiçikdir | AO21: REJECT | AP21: Var | AQ21: Bu halda Skoring Sistemi Musteriye Imtina Verib. Istinsna Hallari Nezere alinaraq ekspertin qarsisina cixarilir. | AU21: TY – Şəxsin yaşı 16-dan kiçikdir
A22: NU – Şəxsin yenilənməmiş aktiv kreditləri mövcuddur | AO22: REJECT | AP22: Var | AQ22: Bu halda Skoring Sistemi Musteriye Imtina Verib. Istinsna Hallari Nezere alinaraq ekspertin qarsisina cixarilir. | AU22: NU – Şəxsin yenilənməmiş aktiv kreditləri mövcuddur
A23: LP – Hüquqi şəxslərə skorların verilməsi nəzərdə tutulmamışdır | AO23: MAYBE | AP23: Yoxdur | AQ23: LP:Hüquqi şəxslərə skorların verilməsi nəzərdə tutulmamışdır. Manual analiz tələb edir
A24: CC – Şəxsin son 12 ay ərzində aktiv öhdəliyi mövcud olmamışdır | AO24: MAYBE | AP24: Yoxdur | AQ24: CC: Şəxsin son 12 ay ərzində aktiv öhdəliyi mövcud olmamışdır.Manual Analiz Teleb Edir
A25: TN – Şəxs qiymətləndirmə üçün çox yenidir | AO25: MAYBE | AP25: Yoxdur | AQ25: TN:Şəxs qiymətləndirmə üçün çox yenidir. Manual Analiz Teleb Edir
A26: NC – Şəxsin hər hansı kredit öhdəliyi mövcud deyil | AO26: MAYBE | AP26: Yoxdur | AQ26: NC:Şəxsin hər hansı kredit öhdəliyi mövcud deyil. Manual Analiz Teleb Edir.
A27: NI: Qeyri Mueyyen Sexs | AO27: MAYBE | AP27: Yoxdur | AQ27: NI: Qeyri Mueyyen Sexs. Manual Analiz Teleb Edir.
A28: AKB Skor Servisi + Vesiqe Melumati uzre yekun bal 1-199 bal | AO28: REJECT | AP28: Var | AQ28: Bu halda Skoring Sistemi Musteriye Imtina Verib. Istinsna Hallari Nezere alinaraq ekspertin qarsisina cixarilir.
A29: AKB Skor Servisi + Vesiqe Melumati uzre yekun bal 200-750 | AO29: MAYBE | AP29: Yoxdur | AQ29: Bu halda ekspert manual analiz edir.
A30: AKB Skor Servisi + Vesiqe Melumati uzre yekun bal 751-1000 | AO30: AVTO YES | AP30: Yoxdur | AQ30: Bu halda Skoring Sistemi Musteriye Kredit Verilmesi ucun Tesdiq Verib.
A31: R_3020 | G31: QƏBUL | K31: Embafinans scoring score is below 200 | Z31: Min. skoring balı | AI31: 200 | AO31: REJECT | AP31: Var | AQ31: Bu halda eskperte is gelib dusmur | AU31: Embafinans Skoring bali 200-den asagidir | BD31: 580 | BG31: =IFERROR(VLOOKUP(BD31,Lookups111!A$4:B$38,2,FALSE()),"") -> Embafinans skoring balı 200-dən aşağıdır | BZ31: 2
A33: Prioritet 4: AKB Tarixçə | AO33: Qerar Sutunu | AP33: Kesim Noqtesi | AQ33: Ekspert Penceresi | AU33: Imtina Sebebi
A34: R_4010 | G34: QƏBUL | K34: Son 24 ay ərzində hər hansı ay üzrə maksimal gecikmə günü 35+ olsa imtina olunsun | Z34: Dövr (ay) | AI34: 24 | AO34: Yoxdur | AP34: Var | AQ34: Bu halda ekspert manual analiz edir. | AU34: Maks gecikma 35+ gün (Son 24 ay) | BD34: 330 | BG34: =IFERROR(VLOOKUP(BD34,Lookups111!A$4:B$38,2,FALSE()),"") -> Maks gecikma 35+ gün (Son 24 ay) | BZ34: 1
Z35: Maks. gecikmə günləri | AI35: 35
A36: R_4020 | G36: QƏBUL | K36: Cari gecikməsi olan kreditlərin ümumi qalıq məbləği (əsas borc və ya faiz borc) 10 azn-dən yuxarı olduqda imtina olunsun | Z36: Min. gecikmə məbləği (AZN) | AI36: 10 | AO36: Yoxdur | AP36: Var | AQ36: Bu halda ekspert manual analiz edir. | AU36: Cari vaxtı keçmiş qalıq > 10 AZN | BD36: 340 | BG36: =IFERROR(VLOOKUP('Cash ABC+ACZ'!BD36,Lookups111!A$4:B$38,2,FALSE()),"") -> Cari vaxtı keçmiş qalıq > 10 AZN | BZ36: 2
A37: R_4025 | G37: QƏBUL | K37: Kredit müqaviləsi bitib | Z37: Min amount (AZN) | AI37: 10 | AO37: Yoxdur | AP37: Var | AQ37: Bu halda ekspert manual analiz edir. | AU37: Kredit müqaviləsi bitib | BD37: 590 | BG37: =IFERROR(VLOOKUP('Cash ABC+ACZ'!BD37,Lookups111!A$4:B$38,2,FALSE()),"") -> Kredit müqaviləsi bitib | BZ37: 3
Z38: Min count | AI38: 0
A39: R_4030 | G39: QƏBUL | K39: Aktiv kreditlərində cari gün gecikməsi olmasın | AO39: Yoxdur | AP39: Var | AQ39: Bu halda ekspert manual analiz edir. | AU39: Cari gün gecikməsi | BD39: 350 | BG39: =IFERROR(VLOOKUP('Cash ABC+ACZ'!BD39,Lookups111!A$4:B$38,2,FALSE()),"") -> Cari gün gecikməsi | BZ39: 4
A40: R_4040 | G40: QƏBUL | K40: Mənfi kredit tarixçəsi | AO40: Yoxdur | AP40: Var | AQ40: Bu halda ekspert manual analiz edir. | AU40: Gecikma əmsalı > 2% | BD40: 360 | BG40: =IFERROR(VLOOKUP('Cash ABC+ACZ'!BD40,Lookups111!A$4:B$38,2,FALSE()),"") -> Gecikma əmsalı > 2% | BZ40: 5
A42: R_4050 | G42: QƏBUL | K42: Aktiv Gündəlik kreditlərinin sayı 1-dən artıq olduqda imtina olunsun | Z42: Maks. Gündəlik kredit sayı (PayDay) | AI42: 1 | AO42: Yoxdur | AP42: Var | AQ42: Bu halda ekspert manual analiz edir. | AU42: Aktiv PayDay kreditləri > 1 | BD42: 370 | BG42: =IFERROR(VLOOKUP('Cash ABC+ACZ'!BD42,Lookups111!A$4:B$38,2,FALSE()),"") -> Aktiv PayDay kreditləri > 1 | BZ42: 6
A43: R_4060 | G43: QƏBUL | K43: Son bir ay ərzində alınmış (aktiv) kreditlərin sayı 2-dən çox olduqda imtina olunsun | Z43: Dövr (ay) | AI43: 1 | AO43: Yoxdur | AP43: Var | AQ43: Bu halda ekspert manual analiz edir. | AU43: Kredit sayı (Son 1 ay) > 2 | BD43: 380 | BG43: =IFERROR(VLOOKUP(BD43,Lookups111!A$4:B$38,2,FALSE()),"") -> Kredit sayı (Son 1 ay) > 2 | BZ43: 7
...

Sheet Cash Cuzdan Wallet
A2: RCASH ÜÇÜN KƏSİM QAYDALARI (ACW) | CI2: ABC + ACZ | CR2: RCASH ÜÇÜN KƏSİM QAYDALARI
A3: Qayda № | G3: Qərar | K3: Qaydanın Təsviri | Z3: Limitlər | AO3: Parametrlər | BD3: İmtina Səbəbi (ID və Mətn) | BU3: X gündən sonra kredit üçün müraciət edə bilər | BZ3: Prioritet
A4: Prioritet 1. Loan Workbench (LW) - Müştərinin Daxili LV sistemində yoxlanması | AO4: Qerar Sutunu | AP4: Kesim Noqtesi | AQ4: Ekspert Penceresi
A5: R_1010 | G5: QƏBUL | K5: Müştəri qara siyahıdadır | AO5: Sistem Avtomatik Imtina Edir | AP5: Var | AQ5: Bu halda eskperte is gelib dusmur | AU5: Qara siyahi | BD5: 010 | BG5: =IFERROR(VLOOKUP('Cash ABC+ACZ'!BD5,Lookups111!A$4:B$38,2,FALSE()),"") -> Qara siyahı | BZ5: 1
A6: R_1020 | G6: QƏBUL | K6: Gəlir kifayət etmir | AO6: REJECT | AP6: Var | AQ6: Bu halda Skoring Sistemi Musteriye Imtina Verib. Istinsna Hallari Nezere alinaraq ekspertin qarsisina cixarilir. | AU6: Gelir kifayet etmir | BD6: 005 | BG6: =IFERROR(VLOOKUP('Cash ABC+ACZ'!BD6,Lookups111!A$4:B$38,2,FALSE()),"") -> Gəliri kifayət etmir | BU6: 15 | BZ6: 2
A7: R_1030 | G7: QƏBUL | K7: Mənfi kredit tarixçəsi | AO7: REJECT | AP7: Var | AQ7: Bu halda Skoring Sistemi Musteriye Imtina Verib. Istinsna Hallari Nezere alinaraq ekspertin qarsisina cixarilir. | AU7: Menfi kredit tarixcesi | BD7: 020 | BG7: =IFERROR(VLOOKUP('Cash ABC+ACZ'!BD7,Lookups111!A$4:B$38,2,FALSE()),"") -> Mənfi kredit tarixçəsi | BU7: 90 | BZ7: 3
A8: R_1040 | G8: QƏBUL | K8: Ailə üzvlərində mənfi tarixçə | AO8: REJECT | AP8: Var | AQ8: Bu halda Skoring Sistemi Musteriye Imtina Verib. Istinsna Hallari Nezere alinaraq ekspertin qarsisina cixarilir. | AU8: Aile uzvlerinin menfi tarixcesi | BD8: 030 | BG8: =IFERROR(VLOOKUP('Cash ABC+ACZ'!BD8,Lookups111!A$4:B$38,2,FALSE()),"") -> Ailə üzvlərinin mənfi tarixçəsi | BU8: 15 | BZ8: 4
A9: R_1050 | G9: QƏBUL | K9: Yanlış məlumat | AO9: REJECT | AP9: Var | AQ9: Bu halda Skoring Sistemi Musteriye Imtina Verib. Istinsna Hallari Nezere alinaraq ekspertin qarsisina cixarilir. | AU9: Yalan melumat | BD9: 070 | BG9: =IFERROR(VLOOKUP('Cash ABC+ACZ'!BD9,Lookups111!A$4:B$38,2,FALSE()),"") -> Yalan məlumat | BU9: 15 | BZ9: 5
A10: R_1060 | G10: QƏBUL | K10: Borc yükü yüksəkdir | AO10: REJECT | AP10: Var | AQ10: Bu halda Skoring Sistemi Musteriye Imtina Verib. Istinsna Hallari Nezere alinaraq ekspertin qarsisina cixarilir. | AU10: Borc yukluliyu coxdur | BD10: 080 | BG10: =IFERROR(VLOOKUP('Cash ABC+ACZ'!BD10,Lookups111!A$4:B$38,2,FALSE()),"") -> Borc yüklülüyü çoxdur | BU10: 3 | BZ10: 6
A11: R_1070 | G11: QƏBUL | K11: İş stajı azdır | AO11: REJECT | AP11: Var | AQ11: Bu halda Skoring Sistemi Musteriye Imtina Verib. Istinsna Hallari Nezere alinaraq ekspertin qarsisina cixarilir. | AU11: Emek staji azdir | BD11: 110 | BG11: =IFERROR(VLOOKUP('Cash ABC+ACZ'!BD11,Lookups111!A$4:B$38,2,FALSE()),"") -> Əmək stajı azdır | BU11: 3 | BZ11: 7
A12: R_1080 | G12: QƏBUL | K12: Kobud rəftar | AO12: REJECT | AP12: Var | AQ12: Bu halda Skoring Sistemi Musteriye Imtina Verib. Istinsna Hallari Nezere alinaraq ekspertin qarsisina cixarilir. | AU12: Kobud reftar | BD12: 120 | BG12: =IFERROR(VLOOKUP('Cash ABC+ACZ'!BD12,Lookups111!A$4:B$38,2,FALSE()),"") -> Kobud rəftar | BU12: 3 | BZ12: 8
A13: R_1090 | G13: QƏBUL | K13: Embafinansda aktiv nağd kreditinin ən azı yarı müddəti keçməmişdir | AO13: REJECT | AP13: Var | AQ13: Bu halda Skoring Sistemi Musteriye Imtina Verib. Istinsna Hallari Nezere alinaraq ekspertin qarsisina cixarilir. | AU13: Aktiv nagd kredit<50% | BD13: 300 | BG13: =IFERROR(VLOOKUP('Cash ABC+ACZ'!BD13,Lookups111!A$4:B$38,2,FALSE()),"") -> Aktiv nağd kredit < 50% | BZ13: 9
A14: R_1100 | G14: QƏBUL | K14: OnePoint platformasında aktiv kreditləri mövcuddur | AO14: REJECT | AP14: Var | AQ14: Bu halda Skoring Sistemi Musteriye Imtina Verib. Istinsna Hallari Nezere alinaraq ekspertin qarsisina cixarilir. | AU14: Aktiv one point kredit | BD14: 310 | BG14: =IFERROR(VLOOKUP('Cash ABC+ACZ'!BD14,Lookups111!A$4:B$38,2,FALSE()),"") -> Aktiv OnePoint krediti | BZ14: 10
A15: R_1110 | G15: QƏBUL | K15: Embafinansda cari gecikməsi mövcuddur | AO15: Sistem Avtomatik Imtina Edir | AP15: Var | AQ15: Bu halda eskperte is gelib dusmur | AU15: Cari gecikma | BD15: 320 | BG15: =IFERROR(VLOOKUP('Cash ABC+ACZ'!BD15,Lookups111!A$4:B$38,2,FALSE()),"") -> Cari gecikma | BZ15: 11
A16: R_1101 | G16: QƏBUL | K16: TY – Şəxsin yaşı 16-dan kiçikdir | AO16: REJECT | AP16: Var | AQ16: Bu halda Skoring Sistemi Musteriye Imtina Verib. Istinsna Hallari Nezere alinaraq ekspertin qarsisina cixarilir. | AU16: TY – Şəxsin yaşı 16-dan kiçikdir | BD16: 310 | BG16: TY – Şəxsin yaşı 16-dan kiçikdir | BU16: ? | BZ16: 12
A17: R_1102 | G17: QƏBUL | K17: NU – Şəxsin yenilənməmiş aktiv kreditləri mövcuddurr | AO17: REJECT | AP17: Var | AQ17: Bu halda Skoring Sistemi Musteriye Imtina Verib. Istinsna Hallari Nezere alinaraq ekspertin qarsisina cixarilir. | AU17: NU – Şəxsin yenilənməmiş aktiv kreditləri mövcuddur | BD17: 310 | BG17: NU – Şəxsin yenilənməmiş aktiv kreditləri mövcuddurr | BU17: ? | BZ17: 13
A18: R_1103 | G18: QƏBUL | K18: AB: Şəxsin cari dövr üzrə aktiv öhdəliyində yüksək gecikmə günləri mövcuddur | AO18: REJECT | AP18: Var | AQ18: Bu halda Skoring Sistemi Musteriye Imtina Verib. Istinsna Hallari Nezere alinaraq ekspertin qarsisina cixarilir. | AU18: AB: Şəxsin cari dövr üzrə aktiv öhdəliyində yüksək gecikmə günləri mövcuddur | BD18: 310 | BG18: AB: Şəxsin cari dövr üzrə aktiv öhdəliyində yüksək gecikmə günləri mövcuddur | BU18: ? | BZ18: 13
A19: Prioritet 2: Asanfinans Şəxsi Məlumatlar
A20: R_2010 | G20: QƏBUL | K20: Yaş həddi | Z20: Min. | AI20: 20 | AO20: Sistem Avtomatik Imtina Edir | AP20: Var | AQ20: Bu halda eskperte is gelib dusmur | AU20: Yaş həddi | BD20: 050 | BG20: =IFERROR(VLOOKUP(BD20,Lookups111!A$4:B$38,2,FALSE()),"") -> Yaş həddi | BZ20: 1
Z21: Maks. | AI21: 65
A22: Prioritet 3: AKB Skor Servisi | AO22: Qerar Sutunu | AP22: Kesim Noqtesi | AQ22: Ekspert Penceresi | AU22: Imtina Sebebi
A23: R_3011 | G23: QƏBUL | K23: AB: Şəxsin cari dövr üzrə aktiv öhdəliyində yüksək gecikmə günləri mövcuddur | AO23: Sistem Avtomatik Imtina Edir | AP23: Var | AQ23: Bu halda eskperte is gelib dusmur | AU23: AB: Şəxsin cari dövr üzrə aktiv öhdəliyində yüksək gecikmə günləri mövcuddur
A24: R_3012 | G24: QƏBUL | K24: AB: Şəxsin cari dövr üzrə aktiv öhdəliyində yüksək gecikmə günləri mövcuddur | AO24: Sistem Avtomatik Imtina Edir | AP24: Var | AQ24: Bu halda eskperte is gelib dusmur | AU24: TY – Şəxsin yaşı 16-dan kiçikdir
A25: R_3013 | G25: QƏBUL | K25: AB: Şəxsin cari dövr üzrə aktiv öhdəliyində yüksək gecikmə günləri mövcuddur | AO25: Sistem Avtomatik Imtina Edir | AP25: Var | AQ25: Bu halda eskperte is gelib dusmur | AU25: NU – Şəxsin yenilənməmiş aktiv kreditləri mövcuddur
A26: LP – Hüquqi şəxslərə skorların verilməsi nəzərdə tutulmamışdır | AO26: MAYBE | AP26: Yoxdur | AQ26: LP:Hüquqi şəxslərə skorların verilməsi nəzərdə tutulmamışdır. Manual analiz tələb edir
A27: CC – Şəxsin son 12 ay ərzində aktiv öhdəliyi mövcud olmamışdır | AO27: MAYBE | AP27: Yoxdur | AQ27: CC: Şəxsin son 12 ay ərzində aktiv öhdəliyi mövcud olmamışdır.Manual Analiz Teleb Edir
A28: TN – Şəxs qiymətləndirmə üçün çox yenidir | AO28: MAYBE | AP28: Yoxdur | AQ28: TN:Şəxs qiymətləndirmə üçün çox yenidir. Manual Analiz Teleb Edir
A29: NC – Şəxsin hər hansı kredit öhdəliyi mövcud deyil | AO29: MAYBE | AP29: Yoxdur | AQ29: NC:Şəxsin hər hansı kredit öhdəliyi mövcud deyil. Manual Analiz Teleb Edir.
A30: NI: Qeyri Mueyyen Sexs | AO30: MAYBE | AP30: Yoxdur | AQ30: NI: Qeyri Mueyyen Sexs. Manual Analiz Teleb Edir.
A31: AKB Skor Servisi + Vesiqe Melumati uzre yekun bal 1-199 bal | AO31: Sistem Avtomatik Imtina Edir | AP31: Var | AQ31: Bu halda eskperte is gelib dusmur
A32: AKB Skor Servisi + Vesiqe Melumati uzre yekun bal 200-750 | AO32: MAYBE | AP32: Yoxdur | AQ32: Bu halda ekspert manual analiz edir.
A33: AKB Skor Servisi + Vesiqe Melumati uzre yekun bal 751-1000 | AO33: AVTO YES | AP33: Yoxdur | AQ33: Bu halda Skoring Sistemi Musteriye Kredit Verilmesi ucun Tesdiq Verib.
A34: R_3020 | G34: QƏBUL | K34: Embafinans scoring score is below 200 | Z34: Min. skoring balı | AI34: 200 | AO34: Sistem Avtomatik Imtina Edir | AP34: Var | AQ34: Bu halda eskperte is gelib dusmur | AU34: Embafinans Skoring bali 200-den asagidir | BD34: 580 | BG34: =IFERROR(VLOOKUP(BD34,Lookups111!A$4:B$38,2,FALSE()),"") -> Embafinans skoring balı 200-dən aşağıdır | BZ34: 2
A36: Prioritet 4: AKB Tarixçə | AO36: Qerar Sutunu | AP36: Kesim Noqtesi | AQ36: Ekspert Penceresi | AU36: Imtina Sebebi
A37: R_4010 | G37: QƏBUL | K37: Son 24 ay ərzində hər hansı ay üzrə maksimal gecikmə günü 35+ olsa imtina olunsun | Z37: Dövr (ay) | AI37: 24 | AO37: Yoxdur | AP37: Var | AQ37: Bu halda ekspert manual analiz edir. | AU37: Maks gecikma 35+ gün (Son 24 ay) | BD37: 330 | BG37: =IFERROR(VLOOKUP(BD37,Lookups111!A$4:B$38,2,FALSE()),"") -> Maks gecikma 35+ gün (Son 24 ay) | BZ37: 1
Z38: Maks. gecikmə günləri | AI38: 35
A39: R_4020 | G39: QƏBUL | K39: Cari gecikməsi olan kreditlərin ümumi qalıq məbləği (əsas borc və ya faiz borc) 10 azn-dən yuxarı olduqda imtina olunsun | Z39: Min. gecikmə məbləği (AZN) | AI39: 10 | AO39: Sistem Avtomatik Imtina Edir | AP39: Var | AQ39: Bu halda eskperte is gelib dusmur | AU39: Cari vaxtı keçmiş qalıq > 10 AZN | BD39: 340 | BG39: =IFERROR(VLOOKUP('Cash Cuzdan Wallet'!BD39,Lookups111!A$4:B$38,2,FALSE()),"") -> Cari vaxtı keçmiş qalıq > 10 AZN | BZ39: 2
A40: R_4025 | G40: QƏBUL | K40: Kredit müqaviləsi bitib | Z40: Min amount (AZN) | AI40: 10 | AO40: Yoxdur | AP40: Var | AQ40: Bu halda ekspert manual analiz edir. | AU40: Kredit müqaviləsi bitib | BD40: 590 | BG40: =IFERROR(VLOOKUP('Cash Cuzdan Wallet'!BD40,Lookups111!A$4:B$38,2,FALSE()),"") -> Kredit müqaviləsi bitib | BZ40: 3
Z41: Min count | AI41: 0
A42: R_4030 | G42: QƏBUL | K42: Aktiv kreditlərində cari gün gecikməsi olmasın | AO42: Sistem Avtomatik Imtina Edir | AP42: Var | AQ42: Bu halda eskperte is gelib dusmur | AU42: Cari gün gecikməsi | BD42: 350 | BG42: =IFERROR(VLOOKUP('Cash Cuzdan Wallet'!BD42,Lookups111!A$4:B$38,2,FALSE()),"") -> Cari gün gecikməsi | BZ42: 4

Sheet RShop EMB
A2: RCASH ÜÇÜN KƏSİM QAYDALARI (RShop EMB) | CI2: ABC + ACZ | CR2: RCASH ÜÇÜN KƏSİM QAYDALARI
A3: Qayda № | G3: Qərar | K3: Qaydanın Təsviri | Z3: Limitlər | AO3: Parametrlər | BD3: İmtina Səbəbi (ID və Mətn) | BU3: X gündən sonra kredit üçün müraciət edə bilər | BZ3: Prioritet
A4: Prioritet 1. Loan Workbench (LW) | AO4: Qerar Sutunu | AP4: Kesim Noqtesi | AQ4: Ekspert Penceresi
A5: R_1010 | G5: QƏBUL | K5: Müştəri qara siyahıdadır | AO5: REJECT | AP5: Var | AQ5: Bu halda Skoring Sistemi Musteriye Imtina Verib. Istinsna Hallari Nezere alinaraq ekspertin qarsisina cixarilir. | AU5: Qara siyahi | BD5: 010 | BG5: =IFERROR(VLOOKUP('Cash ABC+ACZ'!BD5,Lookups111!A$4:B$38,2,FALSE()),"") -> Qara siyahı | BZ5: 1
A6: R_1020 | G6: QƏBUL | K6: Gəlir kifayət etmir | AO6: REJECT | AP6: Var | AQ6: Bu halda Skoring Sistemi Musteriye Imtina Verib. Istinsna Hallari Nezere alinaraq ekspertin qarsisina cixarilir. | AU6: Gelir kifayet etmir | BD6: 005 | BG6: =IFERROR(VLOOKUP('Cash ABC+ACZ'!BD6,Lookups111!A$4:B$38,2,FALSE()),"") -> Gəliri kifayət etmir | BU6: 15 | BZ6: 2
A7: R_1030 | G7: QƏBUL | K7: Mənfi kredit tarixçəsi | AO7: REJECT | AP7: Var | AQ7: Bu halda Skoring Sistemi Musteriye Imtina Verib. Istinsna Hallari Nezere alinaraq ekspertin qarsisina cixarilir. | AU7: Menfi kredit tarixcesi | BD7: 020 | BG7: =IFERROR(VLOOKUP('Cash ABC+ACZ'!BD7,Lookups111!A$4:B$38,2,FALSE()),"") -> Mənfi kredit tarixçəsi | BU7: 90 | BZ7: 3
A8: R_1040 | G8: QƏBUL | K8: Ailə üzvlərində mənfi tarixçə | AO8: REJECT | AP8: Var | AQ8: Bu halda Skoring Sistemi Musteriye Imtina Verib. Istinsna Hallari Nezere alinaraq ekspertin qarsisina cixarilir. | AU8: Aile uzvlerinin menfi tarixcesi | BD8: 030 | BG8: =IFERROR(VLOOKUP('Cash ABC+ACZ'!BD8,Lookups111!A$4:B$38,2,FALSE()),"") -> Ailə üzvlərinin mənfi tarixçəsi | BU8: 15 | BZ8: 4
A9: R_1050 | G9: QƏBUL | K9: Yanlış məlumat | AO9: REJECT | AP9: Var | AQ9: Bu halda Skoring Sistemi Musteriye Imtina Verib. Istinsna Hallari Nezere alinaraq ekspertin qarsisina cixarilir. | AU9: Yalan melumat | BD9: 070 | BG9: =IFERROR(VLOOKUP('Cash ABC+ACZ'!BD9,Lookups111!A$4:B$38,2,FALSE()),"") -> Yalan məlumat | BU9: 15 | BZ9: 5
A10: R_1060 | G10: QƏBUL | K10: Borc yükü yüksəkdir | AO10: REJECT | AP10: Var | AQ10: Bu halda Skoring Sistemi Musteriye Imtina Verib. Istinsna Hallari Nezere alinaraq ekspertin qarsisina cixarilir. | AU10: Borc yukluliyu coxdur | BD10: 080 | BG10: =IFERROR(VLOOKUP('Cash ABC+ACZ'!BD10,Lookups111!A$4:B$38,2,FALSE()),"") -> Borc yüklülüyü çoxdur | BU10: 3 | BZ10: 6
A11: R_1070 | G11: QƏBUL | K11: İş stajı azdır | AO11: REJECT | AP11: Var | AQ11: Bu halda Skoring Sistemi Musteriye Imtina Verib. Istinsna Hallari Nezere alinaraq ekspertin qarsisina cixarilir. | AU11: Emek staji azdir | BD11: 110 | BG11: =IFERROR(VLOOKUP('Cash ABC+ACZ'!BD11,Lookups111!A$4:B$38,2,FALSE()),"") -> Əmək stajı azdır | BU11: 3 | BZ11: 7
A12: R_1080 | G12: QƏBUL | K12: Kobud rəftar | AO12: REJECT | AP12: Var | AQ12: Bu halda Skoring Sistemi Musteriye Imtina Verib. Istinsna Hallari Nezere alinaraq ekspertin qarsisina cixarilir. | AU12: Kobud reftar | BD12: 120 | BG12: =IFERROR(VLOOKUP('Cash ABC+ACZ'!BD12,Lookups111!A$4:B$38,2,FALSE()),"") -> Kobud rəftar | BU12: 3 | BZ12: 8
A13: R_1090 | G13: QƏBUL | K13: Embafinansda aktiv nağd kreditinin ən azı yarı müddəti keçməmişdir | AO13: REJECT | AP13: Var | AQ13: Bu halda Skoring Sistemi Musteriye Imtina Verib. Istinsna Hallari Nezere alinaraq ekspertin qarsisina cixarilir. | AU13: Aktiv nagd kredit<50% | BD13: 300 | BG13: =IFERROR(VLOOKUP('Cash ABC+ACZ'!BD13,Lookups111!A$4:B$38,2,FALSE()),"") -> Aktiv nağd kredit < 50% | BZ13: 9
A14: R_1100 | G14: QƏBUL | K14: OnePoint platformasında aktiv kreditləri mövcuddur | AO14: REJECT | AP14: Var | AQ14: Bu halda Skoring Sistemi Musteriye Imtina Verib. Istinsna Hallari Nezere alinaraq ekspertin qarsisina cixarilir. | AU14: Aktiv one point kredit | BD14: 310 | BG14: =IFERROR(VLOOKUP('Cash ABC+ACZ'!BD14,Lookups111!A$4:B$38,2,FALSE()),"") -> Aktiv OnePoint krediti | BZ14: 10
A15: R_1110 | G15: QƏBUL | K15: Embafinansda cari gecikməsi mövcuddur | AO15: REJECT | AP15: Var | AQ15: Bu halda Skoring Sistemi Musteriye Imtina Verib. Istinsna Hallari Nezere alinaraq ekspertin qarsisina cixarilir. | AU15: Cari gecikme | BD15: 320 | BG15: =IFERROR(VLOOKUP('Cash ABC+ACZ'!BD15,Lookups111!A$4:B$38,2,FALSE()),"") -> Cari gecikma | BZ15: 11
A16: Prioritet 2: Asanfinans Şəxsi Məlumatlar
A17: R_2010 | G17: QƏBUL | K17: Yaş həddi | Z17: Min. | AI17: 20 | AO17: Yoxdur | AP17: Var | AQ17: Bu halda Skoring Sistemi Musteriye Imtina Verib. Istinsna Hallari Nezere alinaraq ekspertin qarsisina cixarilir. | AU17: Yaş həddi | BD17: 050 | BG17: =IFERROR(VLOOKUP(BD17,Lookups111!A$4:B$38,2,FALSE()),"") -> Yaş həddi | BZ17: 1
Z18: Maks. | AI18: 65
A19: Prioritet 3: AKB Skor Servisi | AO19: Qerar Sutunu | AP19: Kesim Noqtesi | AQ19: Ekspert Penceresi
A20: AB: Şəxsin cari dövr üzrə aktiv öhdəliyində yüksək gecikmə günləri mövcuddur | AO20: MAYBE | AP20: Yoxdur | AQ20: AB: Şəxsin cari dövr üzrə aktiv öhdəliyində yüksək gecikmə günləri mövcuddur. Manual Analiz Teleb Edir
A21: TY – Şəxsin yaşı 16-dan kiçikdir | AO21: MAYBE | AP21: Yoxdur | AQ21: TY – Şəxsin yaşı 16-dan kiçikdir. Manual Analiz Teleb Edir
A22: NU – Şəxsin yenilənməmiş aktiv kreditləri mövcuddur | AO22: MAYBE | AP22: Yoxdur | AQ22: NU – Şəxsin yenilənməmiş aktiv kreditləri mövcuddur. Manual Analiz Teleb Edir
A23: LP – Hüquqi şəxslərə skorların verilməsi nəzərdə tutulmamışdır | AO23: MAYBE | AP23: Yoxdur | AQ23: LP:Hüquqi şəxslərə skorların verilməsi nəzərdə tutulmamışdır. Manual analiz tələb edir
A24: CC – Şəxsin son 12 ay ərzində aktiv öhdəliyi mövcud olmamışdır | AO24: MAYBE | AP24: Yoxdur | AQ24: CC: Şəxsin son 12 ay ərzində aktiv öhdəliyi mövcud olmamışdır.Manual Analiz Teleb Edir
A25: TN – Şəxs qiymətləndirmə üçün çox yenidir | AO25: MAYBE | AP25: Yoxdur | AQ25: TN:Şəxs qiymətləndirmə üçün çox yenidir. Manual Analiz Teleb Edir
A26: NC – Şəxsin hər hansı kredit öhdəliyi mövcud deyil | AO26: MAYBE | AP26: Yoxdur | AQ26: NC:Şəxsin hər hansı kredit öhdəliyi mövcud deyil. Manual Analiz Teleb Edir.
A27: NI: Qeyri Mueyyen Sexs | AO27: MAYBE | AP27: Yoxdur | AQ27: NI: Qeyri Mueyyen Sexs. Manual Analiz Teleb Edir.
A28: Prioritet 4: AKB Tarixçə | AO28: Qerar Sutunu | AP28: Kesim Noqtesi | AQ28: Ekspert Penceresi | AU28: Imtina Sebebi
A29: R_4011 | G29: QƏBUL | K29: Cari gecikməsi 30+ gün olan kreditlərin ümumi qalıq məbləği (əsas borc və ya faiz borc) 10 azn-dən yuxarı olduqda imtina olunsun | AO29: Yoxdur | AP29: Var | AQ29: Bu halda ekspert manual analiz edir. | AU29: Gecikmis qaliq > 10 AZN | BD29: 340 | BG29: Gecikmis qaliq > 10 AZN | BZ29: 1
A31: R_4021 | G31: QƏBUL | K31: Aktiv kreditdə cari gecikmə 30 günü keçdikdə imtina olunsun | AO31: Yoxdur | AP31: Var | AQ31: Bu halda ekspert manual analiz edir. | AU31: Aktiv Kredit Gecikmesi | BD31: 480 | BG31: Aktiv Kredit Gecikmesi | BZ31: 2
A32: R_4051 | G32: QƏBUL | K32: Aktiv Gündəlik kreditlərinin sayı 1-dən artıq olduqda imtina olunsun | AO32: Yoxdur | AP32: Var | AQ32: Bu halda ekspert manual analiz edir. | AU32: Aktiv PayDay Kreditleri > 2 | BD32: 371 | BG32: Aktiv PayDay Kreditleri > 2 | BZ32: 3

Sheet RShop  Qeyri-EMB
A2: RCASH ÜÇÜN KƏSİM QAYDALARI (RShop Qeyri-EMB) | CI2: ABC + ACZ | CR2: RCASH ÜÇÜN KƏSİM QAYDALARI
A3: Qayda № | G3: Qərar | K3: Qaydanın Təsviri | Z3: Limitlər | AO3: Parametrlər | BD3: İmtina Səbəbi (ID və Mətn) | BU3: X gündən sonra kredit üçün müraciət edə bilər | BZ3: Prioritet
A4: Prioritet 1. Loan Workbench (LW) | AO4: Qerar Sutunu | AP4: Kesim Noqtesi | AQ4: Ekspert Penceresi
A5: R_1010 | G5: QƏBUL | K5: Müştəri qara siyahıdadır | AO5: REJECT | AP5: Var | AQ5: Bu halda Skoring Sistemi Musteriye Imtina Verib. Istinsna Hallari Nezere alinaraq ekspertin qarsisina cixarilir. | AU5: Qara siyahi | BD5: 010 | BG5: =IFERROR(VLOOKUP('Cash ABC+ACZ'!BD5,Lookups111!A$4:B$38,2,FALSE()),"") -> Qara siyahı | BZ5: 1
A6: R_1020 | G6: QƏBUL | K6: Gəlir kifayət etmir | AO6: REJECT | AP6: Var | AQ6: Bu halda Skoring Sistemi Musteriye Imtina Verib. Istinsna Hallari Nezere alinaraq ekspertin qarsisina cixarilir. | AU6: Gelir kifayet etmir | BD6: 005 | BG6: =IFERROR(VLOOKUP('Cash ABC+ACZ'!BD6,Lookups111!A$4:B$38,2,FALSE()),"") -> Gəliri kifayət etmir | BU6: 15 | BZ6: 2
A7: R_1030 | G7: QƏBUL | K7: Mənfi kredit tarixçəsi | AO7: REJECT | AP7: Var | AQ7: Bu halda Skoring Sistemi Musteriye Imtina Verib. Istinsna Hallari Nezere alinaraq ekspertin qarsisina cixarilir. | AU7: Menfi kredit tarixcesi | BD7: 020 | BG7: =IFERROR(VLOOKUP('Cash ABC+ACZ'!BD7,Lookups111!A$4:B$38,2,FALSE()),"") -> Mənfi kredit tarixçəsi | BU7: 90 | BZ7: 3
A8: R_1040 | G8: QƏBUL | K8: Ailə üzvlərində mənfi tarixçə | AO8: REJECT | AP8: Var | AQ8: Bu halda Skoring Sistemi Musteriye Imtina Verib. Istinsna Hallari Nezere alinaraq ekspertin qarsisina cixarilir. | AU8: Aile uzvlerinin menfi tarixcesi | BD8: 030 | BG8: =IFERROR(VLOOKUP('Cash ABC+ACZ'!BD8,Lookups111!A$4:B$38,2,FALSE()),"") -> Ailə üzvlərinin mənfi tarixçəsi | BU8: 15 | BZ8: 4
A9: R_1050 | G9: QƏBUL | K9: Yanlış məlumat | AO9: REJECT | AP9: Var | AQ9: Bu halda Skoring Sistemi Musteriye Imtina Verib. Istinsna Hallari Nezere alinaraq ekspertin qarsisina cixarilir. | AU9: Yalan melumat | BD9: 070 | BG9: =IFERROR(VLOOKUP('Cash ABC+ACZ'!BD9,Lookups111!A$4:B$38,2,FALSE()),"") -> Yalan məlumat | BU9: 15 | BZ9: 5
A10: R_1060 | G10: QƏBUL | K10: Borc yükü yüksəkdir | AO10: REJECT | AP10: Var | AQ10: Bu halda Skoring Sistemi Musteriye Imtina Verib. Istinsna Hallari Nezere alinaraq ekspertin qarsisina cixarilir. | AU10: Borc yukluliyu coxdur | BD10: 080 | BG10: =IFERROR(VLOOKUP('Cash ABC+ACZ'!BD10,Lookups111!A$4:B$38,2,FALSE()),"") -> Borc yüklülüyü çoxdur | BU10: 3 | BZ10: 6
A11: R_1070 | G11: QƏBUL | K11: İş stajı azdır | AO11: REJECT | AP11: Var | AQ11: Bu halda Skoring Sistemi Musteriye Imtina Verib. Istinsna Hallari Nezere alinaraq ekspertin qarsisina cixarilir. | AU11: Emek staji azdir | BD11: 110 | BG11: =IFERROR(VLOOKUP('Cash ABC+ACZ'!BD11,Lookups111!A$4:B$38,2,FALSE()),"") -> Əmək stajı azdır | BU11: 3 | BZ11: 7
A12: R_1080 | G12: QƏBUL | K12: Kobud rəftar | AO12: REJECT | AP12: Var | AQ12: Bu halda Skoring Sistemi Musteriye Imtina Verib. Istinsna Hallari Nezere alinaraq ekspertin qarsisina cixarilir. | AU12: Kobud reftar | BD12: 120 | BG12: =IFERROR(VLOOKUP('Cash ABC+ACZ'!BD12,Lookups111!A$4:B$38,2,FALSE()),"") -> Kobud rəftar | BU12: 3 | BZ12: 8
A13: R_1090 | G13: QƏBUL | K13: Embafinansda aktiv nağd kreditinin ən azı yarı müddəti keçməmişdir | AO13: REJECT | AP13: Var | AQ13: Bu halda Skoring Sistemi Musteriye Imtina Verib. Istinsna Hallari Nezere alinaraq ekspertin qarsisina cixarilir. | AU13: Aktiv nagd kredit<50% | BD13: 300 | BG13: =IFERROR(VLOOKUP('Cash ABC+ACZ'!BD13,Lookups111!A$4:B$38,2,FALSE()),"") -> Aktiv nağd kredit < 50% | BZ13: 9
A14: R_1100 | G14: QƏBUL | K14: OnePoint platformasında aktiv kreditləri mövcuddur | AO14: REJECT | AP14: Var | AQ14: Bu halda Skoring Sistemi Musteriye Imtina Verib. Istinsna Hallari Nezere alinaraq ekspertin qarsisina cixarilir. | AU14: Aktiv one point kredit | BD14: 310 | BG14: =IFERROR(VLOOKUP('Cash ABC+ACZ'!BD14,Lookups111!A$4:B$38,2,FALSE()),"") -> Aktiv OnePoint krediti | BZ14: 10
A15: R_1110 | G15: QƏBUL | K15: Embafinansda cari gecikməsi mövcuddur | AO15: REJECT | AP15: Var | AQ15: Bu halda Skoring Sistemi Musteriye Imtina Verib. Istinsna Hallari Nezere alinaraq ekspertin qarsisina cixarilir. | AU15: Cari gecikme | BD15: 320 | BG15: =IFERROR(VLOOKUP('Cash ABC+ACZ'!BD15,Lookups111!A$4:B$38,2,FALSE()),"") -> Cari gecikma | BZ15: 11
A16: Prioritet 2: Asanfinans Şəxsi Məlumatlar
A17: R_2010 | G17: QƏBUL | K17: Yaş həddi | Z17: Min. | AI17: 20 | AO17: Yoxdur | AP17: Var | AQ17: Bu halda Skoring Sistemi Musteriye Imtina Verib. Istinsna Hallari Nezere alinaraq ekspertin qarsisina cixarilir. | AU17: Yaş həddi | BD17: 050 | BG17: =IFERROR(VLOOKUP(BD17,Lookups111!A$4:B$38,2,FALSE()),"") -> Yaş həddi | BZ17: 1
Z18: Maks. | AI18: 65
A19: Prioritet 3: AKB Skor Servisi | AO19: Qerar Sutunu | AP19: Kesim Noqtesi | AQ19: Ekspert Penceresi
A20: AB: Şəxsin cari dövr üzrə aktiv öhdəliyində yüksək gecikmə günləri mövcuddur | AO20: MAYBE | AP20: Yoxdur | AQ20: AB: Şəxsin cari dövr üzrə aktiv öhdəliyində yüksək gecikmə günləri mövcuddur. Manual Analiz Teleb Edir
A21: TY – Şəxsin yaşı 16-dan kiçikdir | AO21: MAYBE | AP21: Yoxdur | AQ21: TY – Şəxsin yaşı 16-dan kiçikdir. Manual Analiz Teleb Edir
A22: NU – Şəxsin yenilənməmiş aktiv kreditləri mövcuddur | AO22: MAYBE | AP22: Yoxdur | AQ22: NU – Şəxsin yenilənməmiş aktiv kreditləri mövcuddur. Manual Analiz Teleb Edir
A23: LP – Hüquqi şəxslərə skorların verilməsi nəzərdə tutulmamışdır | AO23: MAYBE | AP23: Yoxdur | AQ23: LP:Hüquqi şəxslərə skorların verilməsi nəzərdə tutulmamışdır. Manual analiz tələb edir
A24: CC – Şəxsin son 12 ay ərzində aktiv öhdəliyi mövcud olmamışdır | AO24: MAYBE | AP24: Yoxdur | AQ24: CC: Şəxsin son 12 ay ərzində aktiv öhdəliyi mövcud olmamışdır.Manual Analiz Teleb Edir
A25: TN – Şəxs qiymətləndirmə üçün çox yenidir | AO25: MAYBE | AP25: Yoxdur | AQ25: TN:Şəxs qiymətləndirmə üçün çox yenidir. Manual Analiz Teleb Edir
A26: NC – Şəxsin hər hansı kredit öhdəliyi mövcud deyil | AO26: MAYBE | AP26: Yoxdur | AQ26: NC:Şəxsin hər hansı kredit öhdəliyi mövcud deyil. Manual Analiz Teleb Edir.
A27: NI: Qeyri Mueyyen Sexs | AO27: MAYBE | AP27: Yoxdur | AQ27: NI: Qeyri Mueyyen Sexs. Manual Analiz Teleb Edir.
A28: Prioritet 4: AKB Tarixçə
A29: R_4011 | G29: QƏBUL | K29: Cari gecikməsi 5+ gün olan kreditlərin ümumi qalıq məbləği (əsas borc və ya faiz borc) 10 azn-dən yuxarı olduqda imtina olunsun | AO29: Yoxdur | AP29: Var | AQ29: Bu halda ekspert manual analiz edir. | AU29: Gecikmis qaliq > 10 AZN | BD29: 340 | BG29: Gecikmis qaliq > 10 AZN | BZ29: 1
A31: R_4021 | G31: QƏBUL | K31: Aktiv kreditdə cari gecikmə 30 günü keçdikdə imtina olunsun | AO31: Yoxdur | AP31: Var | AQ31: Bu halda ekspert manual analiz edir. | AU31: Aktiv Kredit Gecikmesi | BD31: 480 | BG31: Aktiv Kredit Gecikmesi | BZ31: 2
A32: R_4051 | G32: QƏBUL | K32: Aktiv Gündəlik kreditlərinin sayı 1-dən artıq olduqda imtina olunsun | AO32: Yoxdur | AP32: Var | AQ32: Bu halda ekspert manual analiz edir. | AU32: Aktiv PayDay Kreditleri > 2 | BD32: 371 | BG32: Aktiv PayDay Kreditleri > 2 | BZ32: 3

Sheet PayDay WPD
A2: RCASH PAYDAY ÜÇÜN KƏSİM QAYDALARI (WPD+ WCL) | CI2: ABC + ACZ | CR2: RCASH ÜÇÜN KƏSİM QAYDALARI
A3: Qayda № | G3: Qərar | K3: Qaydanın Təsviri | AO3: Parametrlər | BD3: İmtina Səbəbi (ID və Mətn) | BU3: X gündən sonra kredit üçün müraciət edə bilər | BZ3: Prioritet
A4: Prioritet 1. Loan Workbench (LW) | AO4: Qerar Sutunu | AP4: Kesim Noqtesi | AQ4: Ekspert Penceresi
A5: R_1010 | G5: QƏBUL | K5: Müştəri qara siyahıdadır | AO5: Sistem Avtomatik Imtina Edir | AP5: Var | AQ5: Bu halda eskperte is gelib dusmur | AU5: Qara siyahi | BD5: 010 | BG5: =IFERROR(VLOOKUP('Cash ABC+ACZ'!BD5,Lookups111!A$4:B$38,2,FALSE()),"") -> Qara siyahı | BZ5: 1
A6: R_1020 | G6: QƏBUL | K6: Gəlir kifayət etmir | AO6: REJECT | AP6: Var | AQ6: Bu halda Skoring Sistemi Musteriye Imtina Verib. Istinsna Hallari Nezere alinaraq ekspertin qarsisina cixarilir. | AU6: Gelir kifayet etmir | BD6: 005 | BG6: =IFERROR(VLOOKUP('Cash ABC+ACZ'!BD6,Lookups111!A$4:B$38,2,FALSE()),"") -> Gəliri kifayət etmir | BU6: 15 | BZ6: 2
A7: R_1030 | G7: QƏBUL | K7: Mənfi kredit tarixçəsi | AO7: REJECT | AP7: Var | AQ7: Bu halda Skoring Sistemi Musteriye Imtina Verib. Istinsna Hallari Nezere alinaraq ekspertin qarsisina cixarilir. | AU7: Menfi kredit tarixcesi | BD7: 020 | BG7: =IFERROR(VLOOKUP('Cash ABC+ACZ'!BD7,Lookups111!A$4:B$38,2,FALSE()),"") -> Mənfi kredit tarixçəsi | BU7: 90 | BZ7: 3
A8: R_1040 | G8: QƏBUL | K8: Ailə üzvlərində mənfi tarixçə | AO8: REJECT | AP8: Var | AQ8: Bu halda Skoring Sistemi Musteriye Imtina Verib. Istinsna Hallari Nezere alinaraq ekspertin qarsisina cixarilir. | AU8: Aile uzvlerinin menfi tarixcesi | BD8: 030 | BG8: =IFERROR(VLOOKUP('Cash ABC+ACZ'!BD8,Lookups111!A$4:B$38,2,FALSE()),"") -> Ailə üzvlərinin mənfi tarixçəsi | BU8: 15 | BZ8: 4
A9: R_1050 | G9: QƏBUL | K9: Yanlış məlumat | AO9: REJECT | AP9: Var | AQ9: Bu halda Skoring Sistemi Musteriye Imtina Verib. Istinsna Hallari Nezere alinaraq ekspertin qarsisina cixarilir. | AU9: Yalan melumat | BD9: 070 | BG9: =IFERROR(VLOOKUP('Cash ABC+ACZ'!BD9,Lookups111!A$4:B$38,2,FALSE()),"") -> Yalan məlumat | BU9: 15 | BZ9: 5
A10: R_1060 | G10: QƏBUL | K10: Borc yükü yüksəkdir | AO10: REJECT | AP10: Var | AQ10: Bu halda Skoring Sistemi Musteriye Imtina Verib. Istinsna Hallari Nezere alinaraq ekspertin qarsisina cixarilir. | AU10: Borc yukluliyu coxdur | BD10: 080 | BG10: =IFERROR(VLOOKUP('Cash ABC+ACZ'!BD10,Lookups111!A$4:B$38,2,FALSE()),"") -> Borc yüklülüyü çoxdur | BU10: 3 | BZ10: 6
A11: R_1070 | G11: QƏBUL | K11: İş stajı azdır | AO11: REJECT | AP11: Var | AQ11: Bu halda Skoring Sistemi Musteriye Imtina Verib. Istinsna Hallari Nezere alinaraq ekspertin qarsisina cixarilir. | AU11: Emek staji azdir | BD11: 110 | BG11: =IFERROR(VLOOKUP('Cash ABC+ACZ'!BD11,Lookups111!A$4:B$38,2,FALSE()),"") -> Əmək stajı azdır | BU11: 3 | BZ11: 7
A12: R_1080 | G12: QƏBUL | K12: Kobud rəftar | AO12: REJECT | AP12: Var | AQ12: Bu halda Skoring Sistemi Musteriye Imtina Verib. Istinsna Hallari Nezere alinaraq ekspertin qarsisina cixarilir. | AU12: Kobud reftar | BD12: 120 | BG12: =IFERROR(VLOOKUP('Cash ABC+ACZ'!BD12,Lookups111!A$4:B$38,2,FALSE()),"") -> Kobud rəftar | BU12: 3 | BZ12: 8
A13: R_1090 | G13: QƏBUL | K13: Embafinansda aktiv nağd kreditinin ən azı yarı müddəti keçməmişdir | AO13: REJECT | AP13: Var | AQ13: Bu halda Skoring Sistemi Musteriye Imtina Verib. Istinsna Hallari Nezere alinaraq ekspertin qarsisina cixarilir. | AU13: Aktiv nagd kredit<50% | BD13: 300 | BG13: =IFERROR(VLOOKUP('Cash ABC+ACZ'!BD13,Lookups111!A$4:B$38,2,FALSE()),"") -> Aktiv nağd kredit < 50% | BZ13: 9
A14: R_1100 | G14: QƏBUL | K14: OnePoint platformasında aktiv kreditləri mövcuddur | AO14: Sistem Avtomatik Imtina Edir | AP14: Var | AQ14: Bu halda eskperte is gelib dusmur | AU14: Aktiv one point kredit | BD14: 310 | BG14: =IFERROR(VLOOKUP('Cash ABC+ACZ'!BD14,Lookups111!A$4:B$38,2,FALSE()),"") -> Aktiv OnePoint krediti | BZ14: 10
A15: R_1110 | G15: QƏBUL | K15: Embafinansda cari gecikməsi mövcuddur | AO15: Sistem Avtomatik Imtina Edir | AP15: Var | AQ15: Bu halda eskperte is gelib dusmur | AU15: Cari gecikme | BD15: 320 | BG15: =IFERROR(VLOOKUP('Cash ABC+ACZ'!BD15,Lookups111!A$4:B$38,2,FALSE()),"") -> Cari gecikma | BZ15: 11
G16: QƏBUL | K16: Embafinans və OnePointdə layihəsində gündəlik krediti üzrə tam ödəniş etdikdən yalnız 3 iş günü kecmeyib | AO16: REJECT | AP16: Var | AQ16: Bu halda Skoring Sistemi Musteriye Imtina Verib. Istinsna Hallari Nezere alinaraq ekspertin qarsisina cixarilir. | AU16: Embafinans və OnePointdə layihəsində gündəlik krediti üzrə tam ödəniş etdikdən yalnız 3 iş günü kecmeyib | BD16: 320 | BZ16: 11
A17: Prioritet 2: Asanfinans Şəxsi Məlumatlar
A18: R_2010 | G18: QƏBUL | K18: Yaş həddi | Z18: Min. | AI18: 20 | AO18: Sistem Avtomatik Imtina Edir | AP18: Var | AQ18: Bu halda eskperte is gelib dusmur | AU18: Yaş həddi | BD18: 050 | BG18: =IFERROR(VLOOKUP(BD18,Lookups111!A$4:B$38,2,FALSE()),"") -> Yaş həddi | BZ18: 1
Z19: Maks. | AI19: 65
A20: Prioritet 3: AKB Skor Servisi | AO20: Qerar Sutunu | AP20: Kesim Noqtesi | AQ20: Ekspert Penceresi
A21: AB: Şəxsin cari dövr üzrə aktiv öhdəliyində yüksək gecikmə günləri mövcuddur | AO21: Sistem Avtomatik Imtina Edir | AP21: Var | AQ21: Bu halda eskperte is gelib dusmur | AU21: AB: Şəxsin cari dövr üzrə aktiv öhdəliyində yüksək gecikmə günləri mövcuddur
A22: TY – Şəxsin yaşı 16-dan kiçikdir | AO22: Sistem Avtomatik Imtina Edir | AP22: Var | AQ22: Bu halda eskperte is gelib dusmur | AU22: TY – Şəxsin yaşı 16-dan kiçikdir
A23: NU – Şəxsin yenilənməmiş aktiv kreditləri mövcuddur | AO23: Sistem Avtomatik Imtina Edir | AP23: Var | AQ23: Bu halda eskperte is gelib dusmur | AU23: NU – Şəxsin yenilənməmiş aktiv kreditləri mövcuddur
A24: LP – Hüquqi şəxslərə skorların verilməsi nəzərdə tutulmamışdır | AO24: MAYBE | AP24: Yoxdur | AQ24: LP:Hüquqi şəxslərə skorların verilməsi nəzərdə tutulmamışdır. Manual analiz tələb edir
A25: CC – Şəxsin son 12 ay ərzində aktiv öhdəliyi mövcud olmamışdır | AO25: MAYBE | AP25: Yoxdur | AQ25: CC: Şəxsin son 12 ay ərzində aktiv öhdəliyi mövcud olmamışdır.Manual Analiz Teleb Edir
A26: TN – Şəxs qiymətləndirmə üçün çox yenidir | AO26: MAYBE | AP26: Yoxdur | AQ26: TN:Şəxs qiymətləndirmə üçün çox yenidir. Manual Analiz Teleb Edir
A27: NC – Şəxsin hər hansı kredit öhdəliyi mövcud deyil | AO27: MAYBE | AP27: Yoxdur | AQ27: NC:Şəxsin hər hansı kredit öhdəliyi mövcud deyil. Manual Analiz Teleb Edir.
A28: NI: Qeyri Mueyyen Sexs | AO28: MAYBE | AP28: Yoxdur | AQ28: NI: Qeyri Mueyyen Sexs. Manual Analiz Teleb Edir.
A29: AKB Skor Servisi + Vesiqe Melumati uzre yekun bal 1-199 bal | AO29: REJECT | AP29: Var | AQ29: Bu halda Skoring Sistemi Musteriye Imtina Verib. Istinsna Hallari Nezere alinaraq ekspertin qarsisina cixarilir.
A30: AKB Skor Servisi + Vesiqe Melumati uzre yekun bal 200-750 | AO30: MAYBE | AP30: Yoxdur | AQ30: Bu halda ekspert manual analiz edir.
A31: AKB Skor Servisi + Vesiqe Melumati uzre yekun bal 751-1000 | AO31: AVTO YES | AP31: Yoxdur | AQ31: Bu halda Skoring Sistemi Musteriye Kredit Verilmesi ucun Tesdiq Verib.
A32: R_3020 | G32: QƏBUL | K32: Embafinans scoring score is below 100 | Z32: Min. skoring balı | AI32: 100 | AO32: REJECT | AP32: Var | AQ32: Bu halda eskperte is gelib dusmur | AU32: Embafinans Skoring bali 100-den asagidir | BD32: 580 | BG32: Embafinans skoring balı 100-dən aşağıdır | BZ32: 2
A34: Prioritet 4: AKB Tarixçə | AO34: Qerar Sutunu | AP34: Kesim Noqtesi | AQ34: Ekspert Penceresi | AU34: Imtina Sebebi
G35: QƏBUL | K35: Gecikmə günləri üzrə əmsal 6%-dən yüksək olduqda imtina olunsun | AO35: Yoxdur | AP35: Var | AQ35: Bu halda ekspert manual analiz edir. | AU35: Gecikmə günləri üzrə əmsal 6%-dən yüksək olduqda imtina olunsun | BD35: 330 | BG35: Gecikmə günləri üzrə əmsal 6%-dən yüksək olduqda imtina olunsun | BZ35: 1
G37: QƏBUL | K37: Son 12 ayda maksimal gecikme muddeti bir gecikmə üzrə 15+ olduqda imtina olunsun | AO37: Yoxdur | AP37: Var | AQ37: Bu halda ekspert manual analiz edir. | AU37: Son 12 ayda maksimal gecikme muddeti bir gecikmə üzrə 15+ olduqda imtina olunsun | BD37: 340 | BG37: =IFERROR(VLOOKUP('Cash Cuzdan Wallet'!BD35,Lookups111!A$4:B$38,2,FALSE()),"") | BZ37: 2
A38: R_4030 | G38: QƏBUL | K38: Aktiv kreditlərində cari gün gecikməsi olmasın | AO38: Yoxdur | AP38: Var | AQ38: Bu halda ekspert manual analiz edir. | AU38: Cari gün gecikməsi | BD38: 350 | BG38: car gun gecikmesi | BZ38: 4
G39: QƏBUL | K39: Son 6 ayda gündəlik krediti olmayan müştəriyə imtina olunsun | AO39: Yoxdur | AP39: Var | AQ39: Bu halda ekspert manual analiz edir. | AU39: Son 6 ayda gündəlik krediti olmayan müştəriyə imtina olunsun | BD39: 590 | BG39: Son 6 ayda gündəlik krediti olmayan müştəriyə imtina olunsun | BZ39: 3
G41: QƏBUL | K41: Aktiv kredit tarixçəsi 9 aydan az olduqda imtina olunsun | AO41: Yoxdur | AP41: Var | AQ41: Bu halda ekspert manual analiz edir. | AU41: Aktiv kredit tarixçəsi 9 aydan az olduqda imtina olunsun | BD41: 350 | BG41: Aktiv kredit tarixçəsi 9 aydan az olduqda imtina olunsun | BZ41: 4
G42: QƏBUL | K42: Aktiv aylıq ödənişlərin cəmi 3000azn-dən artıq olduqda imtina olunsun | AO42: Yoxdur | AP42: Var | AQ42: Bu halda ekspert manual analiz edir. | AU42: Aktiv aylıq ödənişlərin cəmi 3000azn-dən artıq olduqda imtina olunsun | BD42: 360 | BG42: Aktiv aylıq ödənişlərin cəmi 3000azn-dən artıq olduqda imtina olunsun | BZ42: 5

Sheet PayDay WCL
A2: RCASH PAYDAY ÜÇÜN KƏSİM QAYDALARI (WPD+ WCL) | CI2: ABC + ACZ | CR2: RCASH ÜÇÜN KƏSİM QAYDALARI
A3: Qayda № | G3: Qərar | K3: Qaydanın Təsviri | Z3: Limitlər | AO3: Parametrlər | BD3: İmtina Səbəbi (ID və Mətn) | BU3: X gündən sonra kredit üçün müraciət edə bilər | BZ3: Prioritet
A4: Prioritet 1. Loan Workbench (LW) | AO4: Qerar Sutunu | AP4: Kesim Noqtesi | AQ4: Ekspert Penceresi
A5: R_1010 | G5: QƏBUL | K5: Müştəri qara siyahıdadır | AO5: Sistem Avtomatik Imtina Edir | AP5: Var | AQ5: Bu halda eskperte is gelib dusmur | AU5: Qara siyahi | BD5: 010 | BG5: =IFERROR(VLOOKUP('Cash ABC+ACZ'!BD5,Lookups111!A$4:B$38,2,FALSE()),"") -> Qara siyahı | BZ5: 1
A6: R_1020 | G6: QƏBUL | K6: Gəlir kifayət etmir | AO6: REJECT | AP6: Var | AQ6: Bu halda Skoring Sistemi Musteriye Imtina Verib. Istinsna Hallari Nezere alinaraq ekspertin qarsisina cixarilir. | AU6: Gelir kifayet etmir | BD6: 005 | BG6: =IFERROR(VLOOKUP('Cash ABC+ACZ'!BD6,Lookups111!A$4:B$38,2,FALSE()),"") -> Gəliri kifayət etmir | BU6: 15 | BZ6: 2
A7: R_1030 | G7: QƏBUL | K7: Mənfi kredit tarixçəsi | AO7: REJECT | AP7: Var | AQ7: Bu halda Skoring Sistemi Musteriye Imtina Verib. Istinsna Hallari Nezere alinaraq ekspertin qarsisina cixarilir. | AU7: Menfi kredit tarixcesi | BD7: 020 | BG7: =IFERROR(VLOOKUP('Cash ABC+ACZ'!BD7,Lookups111!A$4:B$38,2,FALSE()),"") -> Mənfi kredit tarixçəsi | BU7: 90 | BZ7: 3
A8: R_1040 | G8: QƏBUL | K8: Ailə üzvlərində mənfi tarixçə | AO8: REJECT | AP8: Var | AQ8: Bu halda Skoring Sistemi Musteriye Imtina Verib. Istinsna Hallari Nezere alinaraq ekspertin qarsisina cixarilir. | AU8: Aile uzvlerinin menfi tarixcesi | BD8: 030 | BG8: =IFERROR(VLOOKUP('Cash ABC+ACZ'!BD8,Lookups111!A$4:B$38,2,FALSE()),"") -> Ailə üzvlərinin mənfi tarixçəsi | BU8: 15 | BZ8: 4
A9: R_1050 | G9: QƏBUL | K9: Yanlış məlumat | AO9: REJECT | AP9: Var | AQ9: Bu halda Skoring Sistemi Musteriye Imtina Verib. Istinsna Hallari Nezere alinaraq ekspertin qarsisina cixarilir. | AU9: Yalan melumat | BD9: 070 | BG9: =IFERROR(VLOOKUP('Cash ABC+ACZ'!BD9,Lookups111!A$4:B$38,2,FALSE()),"") -> Yalan məlumat | BU9: 15 | BZ9: 5
A10: R_1060 | G10: QƏBUL | K10: Borc yükü yüksəkdir | AO10: REJECT | AP10: Var | AQ10: Bu halda Skoring Sistemi Musteriye Imtina Verib. Istinsna Hallari Nezere alinaraq ekspertin qarsisina cixarilir. | AU10: Borc yukluliyu coxdur | BD10: 080 | BG10: =IFERROR(VLOOKUP('Cash ABC+ACZ'!BD10,Lookups111!A$4:B$38,2,FALSE()),"") -> Borc yüklülüyü çoxdur | BU10: 3 | BZ10: 6
A11: R_1070 | G11: QƏBUL | K11: İş stajı azdır | AO11: REJECT | AP11: Var | AQ11: Bu halda Skoring Sistemi Musteriye Imtina Verib. Istinsna Hallari Nezere alinaraq ekspertin qarsisina cixarilir. | AU11: Emek staji azdir | BD11: 110 | BG11: =IFERROR(VLOOKUP('Cash ABC+ACZ'!BD11,Lookups111!A$4:B$38,2,FALSE()),"") -> Əmək stajı azdır | BU11: 3 | BZ11: 7
A12: R_1080 | G12: QƏBUL | K12: Kobud rəftar | AO12: REJECT | AP12: Var | AQ12: Bu halda Skoring Sistemi Musteriye Imtina Verib. Istinsna Hallari Nezere alinaraq ekspertin qarsisina cixarilir. | AU12: Kobud reftar | BD12: 120 | BG12: =IFERROR(VLOOKUP('Cash ABC+ACZ'!BD12,Lookups111!A$4:B$38,2,FALSE()),"") -> Kobud rəftar | BU12: 3 | BZ12: 8
A13: R_1090 | G13: QƏBUL | K13: Embafinansda aktiv nağd kreditinin ən azı yarı müddəti keçməmişdir | AO13: REJECT | AP13: Var | AQ13: Bu halda Skoring Sistemi Musteriye Imtina Verib. Istinsna Hallari Nezere alinaraq ekspertin qarsisina cixarilir. | AU13: Aktiv nagd kredit<50% | BD13: 300 | BG13: =IFERROR(VLOOKUP('Cash ABC+ACZ'!BD13,Lookups111!A$4:B$38,2,FALSE()),"") -> Aktiv nağd kredit < 50% | BZ13: 9
A14: R_1100 | G14: QƏBUL | K14: OnePoint platformasında aktiv kreditləri mövcuddur | AO14: Sistem Avtomatik Imtina Edir | AP14: Var | AQ14: Bu halda Skoring Sistemi Musteriye Imtina Verib. Istinsna Hallari Nezere alinaraq ekspertin qarsisina cixarilir. | AU14: Aktiv one point kredit | BD14: 310 | BG14: =IFERROR(VLOOKUP('Cash ABC+ACZ'!BD14,Lookups111!A$4:B$38,2,FALSE()),"") -> Aktiv OnePoint krediti | BZ14: 10
A15: R_1110 | G15: QƏBUL | K15: Embafinansda cari gecikməsi mövcuddur | AO15: Sistem Avtomatik Imtina Edir | AP15: Var | AQ15: Bu halda Skoring Sistemi Musteriye Imtina Verib. Istinsna Hallari Nezere alinaraq ekspertin qarsisina cixarilir. | AU15: Cari gecikme | BD15: 320 | BG15: =IFERROR(VLOOKUP('Cash ABC+ACZ'!BD15,Lookups111!A$4:B$38,2,FALSE()),"") -> Cari gecikma | BZ15: 11
A16: Prioritet 2: Asanfinans Şəxsi Məlumatlar
A17: R_2010 | G17: QƏBUL | K17: Yaş həddi | Z17: Min. | AI17: 20 | AO17: Sistem Avtomatik Imtina Edir | AP17: Var | AQ17: Bu halda Skoring Sistemi Musteriye Imtina Verib. Istinsna Hallari Nezere alinaraq ekspertin qarsisina cixarilir. | AU17: Yaş həddi | BD17: 050 | BG17: =IFERROR(VLOOKUP(BD17,Lookups111!A$4:B$38,2,FALSE()),"") -> Yaş həddi | BZ17: 1
Z18: Maks. | AI18: 65
A19: Prioritet 3: AKB Skor Servisi | AO19: Qerar Sutunu | AP19: Kesim Noqtesi | AQ19: Ekspert Penceresi
A20: AB: Şəxsin cari dövr üzrə aktiv öhdəliyində yüksək gecikmə günləri mövcuddur | AO20: Sistem Avtomatik Imtina Edir | AP20: Var | AQ20: Bu halda Skoring Sistemi Musteriye Imtina Verib. Istinsna Hallari Nezere alinaraq ekspertin qarsisina cixarilir. | AU20: AB: Şəxsin cari dövr üzrə aktiv öhdəliyində yüksək gecikmə günləri mövcuddur
A21: TY – Şəxsin yaşı 16-dan kiçikdir | AO21: Sistem Avtomatik Imtina Edir | AP21: Var | AQ21: Bu halda Skoring Sistemi Musteriye Imtina Verib. Istinsna Hallari Nezere alinaraq ekspertin qarsisina cixarilir. | AU21: TY – Şəxsin yaşı 16-dan kiçikdir
A22: NU – Şəxsin yenilənməmiş aktiv kreditləri mövcuddur | AO22: Sistem Avtomatik Imtina Edir | AP22: Var | AQ22: Bu halda Skoring Sistemi Musteriye Imtina Verib. Istinsna Hallari Nezere alinaraq ekspertin qarsisina cixarilir. | AU22: NU – Şəxsin yenilənməmiş aktiv kreditləri mövcuddur
A23: LP – Hüquqi şəxslərə skorların verilməsi nəzərdə tutulmamışdır | AO23: MAYBE | AP23: Yoxdur | AQ23: LP:Hüquqi şəxslərə skorların verilməsi nəzərdə tutulmamışdır. Manual analiz tələb edir
A24: CC – Şəxsin son 12 ay ərzində aktiv öhdəliyi mövcud olmamışdır | AO24: MAYBE | AP24: Yoxdur | AQ24: CC: Şəxsin son 12 ay ərzində aktiv öhdəliyi mövcud olmamışdır.Manual Analiz Teleb Edir
A25: TN – Şəxs qiymətləndirmə üçün çox yenidir | AO25: MAYBE | AP25: Yoxdur | AQ25: TN:Şəxs qiymətləndirmə üçün çox yenidir. Manual Analiz Teleb Edir
A26: NC – Şəxsin hər hansı kredit öhdəliyi mövcud deyil | AO26: MAYBE | AP26: Yoxdur | AQ26: NC:Şəxsin hər hansı kredit öhdəliyi mövcud deyil. Manual Analiz Teleb Edir.
A27: NI: Qeyri Mueyyen Sexs | AO27: MAYBE | AP27: Yoxdur | AQ27: NI: Qeyri Mueyyen Sexs. Manual Analiz Teleb Edir.
A28: AKB Skor Servisi + Vesiqe Melumati uzre yekun bal 1-199 bal | AO28: REJECT | AP28: Var | AQ28: Bu halda Skoring Sistemi Musteriye Imtina Verib. Istinsna Hallari Nezere alinaraq ekspertin qarsisina cixarilir.
A29: AKB Skor Servisi + Vesiqe Melumati uzre yekun bal 200-750 | AO29: MAYBE | AP29: Yoxdur | AQ29: Bu halda ekspert manual analiz edir.
A30: AKB Skor Servisi + Vesiqe Melumati uzre yekun bal 751-1000 | AO30: AVTO YES | AP30: Yoxdur | AQ30: Bu halda Skoring Sistemi Musteriye Kredit Verilmesi ucun Tesdiq Verib.
A31: R_3020 | G31: QƏBUL | K31: Embafinans scoring score is below 100 | Z31: Min. skoring balı | AI31: 100 | AO31: REJECT | AP31: Var | AQ31: Bu halda eskperte is gelib dusmur | AU31: Embafinans Skoring bali 100-den asagidir | BD31: 580 | BG31: Embafinans skoring balı 100-dən aşağıdır | BZ31: 2
A33: Prioritet 4: AKB Tarixçə | AO33: Qerar Sutunu | AP33: Kesim Noqtesi | AQ33: Ekspert Penceresi | AU33: Imtina Sebebi
G34: QƏBUL | K34: Gecikmə günləri üzrə əmsal 6%-dən yüksək olduqda imtina olunsun | AO34: Yoxdur | AP34: Var | AQ34: Bu halda ekspert manual analiz edir. | AU34: Gecikmə günləri üzrə əmsal 6%-dən yüksək olduqda imtina olunsun | BD34: 330 | BG34: Gecikmə günləri üzrə əmsal 6%-dən yüksək olduqda imtina olunsun | BZ34: 1
G36: QƏBUL | K36: Son 12 ayda maksimal gecikme muddeti bir gecikmə üzrə 15+ olduqda imtina olunsun | AO36: Yoxdur | AP36: Var | AQ36: Bu halda ekspert manual analiz edir. | AU36: Son 12 ayda maksimal gecikme muddeti bir gecikmə üzrə 15+ olduqda imtina olunsun | BD36: 340 | BG36: =IFERROR(VLOOKUP('Cash Cuzdan Wallet'!BD35,Lookups111!A$4:B$38,2,FALSE()),"") | BZ36: 2
A37: R_4030 | G37: QƏBUL | K37: Aktiv kreditlərində cari gün gecikməsi olmasın | AO37: Yoxdur | AP37: Var | AQ37: Bu halda ekspert manual analiz edir. | AU37: Cari gün gecikməsi | BD37: 350 | BG37: car gun gecikmesi | BZ37: 4
G38: QƏBUL | K38: Son 6 ayda gündəlik krediti olmayan müştəriyə imtina olunsun | AO38: Yoxdur | AP38: Var | AQ38: Bu halda ekspert manual analiz edir. | AU38: Son 6 ayda gündəlik krediti olmayan müştəriyə imtina olunsun | BD38: 590 | BG38: Son 6 ayda gündəlik krediti olmayan müştəriyə imtina olunsun | BZ38: 3
G40: QƏBUL | K40: Aktiv kredit tarixçəsi 9 aydan az olduqda imtina olunsun | AO40: Yoxdur | AP40: Var | AQ40: Bu halda ekspert manual analiz edir. | AU40: Aktiv kredit tarixçəsi 9 aydan az olduqda imtina olunsun | BD40: 350 | BG40: Aktiv kredit tarixçəsi 9 aydan az olduqda imtina olunsun | BZ40: 4
G41: QƏBUL | K41: Aktiv aylıq ödənişlərin cəmi 3000azn-dən artıq olduqda imtina olunsun | AO41: Yoxdur | AP41: Var | AQ41: Bu halda ekspert manual analiz edir. | AU41: Aktiv aylıq ödənişlərin cəmi 3000azn-dən artıq olduqda imtina olunsun | BD41: 360 | BG41: Aktiv aylıq ödənişlərin cəmi 3000azn-dən artıq olduqda imtina olunsun | BZ41: 5
A43: Prioritet 5: AsanFinans İş yeri və Təqaüd
A44: R_5010 | G44: QƏBUL | K44: Rəsmi iş yeri hüquqi şəxsə aid olsun | AO44: Yoxdur | AP44: Var | AQ44: Bu halda ekspert manual analiz edir. | AU44: Resmi is yeri ve pensiya yoxdur | BD44: 400 | BG44: =IFERROR(VLOOKUP(BD44,Lookups111!A$4:B$38,2,FALSE()),"") -> Rəsmi iş yeri və pensiya yoxdur | BZ44: 1
A46: R_5020 | G46: QƏBUL | K46: Son iş yerində ən azı 6 ay staj | Z46: Min. staj (ay) | AI46: 6 | AO46: Yoxdur | AP46: Var | AQ46: Bu halda ekspert manual analiz edir. | AU46: Cari is staji < 6 ay | BD46: 410 | BG46: =IFERROR(VLOOKUP(BD46,Lookups111!A$4:B$38,2,FALSE()),"") -> Cari iş stajı < 6 ay | BZ46: 2
...

Sheet Lookups111
A2: Rejection Reason
A3: id | B3: text
A4: 370 | B4: Aktiv PayDay kreditləri > 1
A5: 450 | B5: Pensiya < 400 AZN & Tarixçə yoxdur
A6: 380 | B6: Kredit sayı (Son 1 ay) > 2
A7: 430 | B7: İş yeri Fiziki şəxs & Tarixçə yoxdur
A8: 300 | B8: Aktiv nağd kredit < 50%
A9: 480 | B9: Aktiv kredit gecikməsi
A10: 020 | B10: Mənfi kredit tarixçəsi
A11: 070 | B11: Yalan məlumat
A12: 350 | B12: Cari gün gecikməsi
A13: 420 | B13: Müqavilə bitməsi <= 10 gün
A14: 050 | B14: Yaş həddi
... A37: 371 | B37: Aktiv PayDay kreditləri > 2
